[2025-04-27T15:12:48.042+0000] {taskinstance.py:1956} INFO - Dependencies all met for dep_context=non-requeueable deps ti=<TaskInstance: email_sender.transform_data manual__2025-04-27T15:12:46.389976+00:00 [queued]>
[2025-04-27T15:12:48.045+0000] {taskinstance.py:1956} INFO - Dependencies all met for dep_context=requeueable deps ti=<TaskInstance: email_sender.transform_data manual__2025-04-27T15:12:46.389976+00:00 [queued]>
[2025-04-27T15:12:48.045+0000] {taskinstance.py:2170} INFO - Starting attempt 1 of 1
[2025-04-27T15:12:48.111+0000] {taskinstance.py:2191} INFO - Executing <Task(PythonOperator): transform_data> on 2025-04-27 15:12:46.389976+00:00
[2025-04-27T15:12:48.113+0000] {standard_task_runner.py:60} INFO - Started process 135 to run task
[2025-04-27T15:12:48.114+0000] {standard_task_runner.py:87} INFO - Running: ['***', 'tasks', 'run', 'email_sender', 'transform_data', 'manual__2025-04-27T15:12:46.389976+00:00', '--job-id', '16', '--raw', '--subdir', 'DAGS_FOLDER/email_sender_dag.py', '--cfg-path', '/tmp/tmpsq07ovw7']
[2025-04-27T15:12:48.115+0000] {standard_task_runner.py:88} INFO - Job 16: Subtask transform_data
[2025-04-27T15:12:48.130+0000] {task_command.py:423} INFO - Running <TaskInstance: email_sender.transform_data manual__2025-04-27T15:12:46.389976+00:00 [running]> on host 7eeb628339b5
[2025-04-27T15:12:48.154+0000] {taskinstance.py:2480} INFO - Exporting env vars: AIRFLOW_CTX_DAG_OWNER='***' AIRFLOW_CTX_DAG_ID='email_sender' AIRFLOW_CTX_TASK_ID='transform_data' AIRFLOW_CTX_EXECUTION_DATE='2025-04-27T15:12:46.389976+00:00' AIRFLOW_CTX_TRY_NUMBER='1' AIRFLOW_CTX_DAG_RUN_ID='manual__2025-04-27T15:12:46.389976+00:00'
[2025-04-27T15:12:48.164+0000] {taskinstance.py:2698} ERROR - Task failed with exception
Traceback (most recent call last):
  File "/home/airflow/.local/lib/python3.8/site-packages/airflow/models/taskinstance.py", line 433, in _execute_task
    result = execute_callable(context=context, **execute_callable_kwargs)
  File "/home/airflow/.local/lib/python3.8/site-packages/airflow/operators/python.py", line 199, in execute
    return_value = self.execute_callable()
  File "/home/airflow/.local/lib/python3.8/site-packages/airflow/operators/python.py", line 216, in execute_callable
    return self.python_callable(*self.op_args, **self.op_kwargs)
  File "/opt/airflow/dags/email_sender_dag.py", line 83, in transform_data
    os.makedirs(output_dir, exist_ok=True)
  File "/usr/local/lib/python3.8/os.py", line 208, in makedirs
    head, tail = path.split(name)
  File "/usr/local/lib/python3.8/posixpath.py", line 103, in split
    p = os.fspath(p)
TypeError: expected str, bytes or os.PathLike object, not NoneType
[2025-04-27T15:12:48.168+0000] {taskinstance.py:1138} INFO - Marking task as FAILED. dag_id=email_sender, task_id=transform_data, execution_date=20250427T151246, start_date=20250427T151248, end_date=20250427T151248
[2025-04-27T15:12:48.173+0000] {standard_task_runner.py:107} ERROR - Failed to execute job 16 for task transform_data (expected str, bytes or os.PathLike object, not NoneType; 135)
[2025-04-27T15:12:48.212+0000] {local_task_job_runner.py:234} INFO - Task exited with return code 1
[2025-04-27T15:12:48.222+0000] {taskinstance.py:3280} INFO - 0 downstream tasks scheduled from follow-on schedule check
