[2025-04-25T00:13:41.545+0000] {taskinstance.py:1956} INFO - Dependencies all met for dep_context=non-requeueable deps ti=<TaskInstance: email_sender.extract_data manual__2025-04-25T00:13:41.151021+00:00 [queued]>
[2025-04-25T00:13:41.548+0000] {taskinstance.py:1956} INFO - Dependencies all met for dep_context=requeueable deps ti=<TaskInstance: email_sender.extract_data manual__2025-04-25T00:13:41.151021+00:00 [queued]>
[2025-04-25T00:13:41.549+0000] {taskinstance.py:2170} INFO - Starting attempt 1 of 1
[2025-04-25T00:13:41.553+0000] {taskinstance.py:2191} INFO - Executing <Task(PythonOperator): extract_data> on 2025-04-25 00:13:41.151021+00:00
[2025-04-25T00:13:41.555+0000] {standard_task_runner.py:60} INFO - Started process 183 to run task
[2025-04-25T00:13:41.557+0000] {standard_task_runner.py:87} INFO - Running: ['***', 'tasks', 'run', 'email_sender', 'extract_data', 'manual__2025-04-25T00:13:41.151021+00:00', '--job-id', '10', '--raw', '--subdir', 'DAGS_FOLDER/email_sender_dag.py', '--cfg-path', '/tmp/tmpokhl7ymn']
[2025-04-25T00:13:41.558+0000] {standard_task_runner.py:88} INFO - Job 10: Subtask extract_data
[2025-04-25T00:13:41.680+0000] {task_command.py:423} INFO - Running <TaskInstance: email_sender.extract_data manual__2025-04-25T00:13:41.151021+00:00 [running]> on host 11cd846e23bd
[2025-04-25T00:13:41.706+0000] {taskinstance.py:2480} INFO - Exporting env vars: AIRFLOW_CTX_DAG_OWNER='***' AIRFLOW_CTX_DAG_ID='email_sender' AIRFLOW_CTX_TASK_ID='extract_data' AIRFLOW_CTX_EXECUTION_DATE='2025-04-25T00:13:41.151021+00:00' AIRFLOW_CTX_TRY_NUMBER='1' AIRFLOW_CTX_DAG_RUN_ID='manual__2025-04-25T00:13:41.151021+00:00'
[2025-04-25T00:13:41.709+0000] {base.py:83} INFO - Using connection ID 'postgresql_padrao' for task execution.
[2025-04-25T00:13:41.715+0000] {taskinstance.py:2698} ERROR - Task failed with exception
Traceback (most recent call last):
  File "/home/airflow/.local/lib/python3.8/site-packages/airflow/models/taskinstance.py", line 433, in _execute_task
    result = execute_callable(context=context, **execute_callable_kwargs)
  File "/home/airflow/.local/lib/python3.8/site-packages/airflow/operators/python.py", line 199, in execute
    return_value = self.execute_callable()
  File "/home/airflow/.local/lib/python3.8/site-packages/airflow/operators/python.py", line 216, in execute_callable
    return self.python_callable(*self.op_args, **self.op_kwargs)
  File "/opt/airflow/dags/email_sender_dag.py", line 58, in extract_data
    conn = pg_hook.get_conn()
  File "/home/airflow/.local/lib/python3.8/site-packages/airflow/providers/postgres/hooks/postgres.py", line 158, in get_conn
    self.conn = psycopg2.connect(**conn_args)
  File "/home/airflow/.local/lib/python3.8/site-packages/psycopg2/__init__.py", line 122, in connect
    conn = _connect(dsn, connection_factory=connection_factory, **kwasync)
psycopg2.OperationalError: connection to server at "host.docker.internal" (192.168.65.254), port 5432 failed: fe_sendauth: no password supplied

[2025-04-25T00:13:41.718+0000] {taskinstance.py:1138} INFO - Marking task as FAILED. dag_id=email_sender, task_id=extract_data, execution_date=20250425T001341, start_date=20250425T001341, end_date=20250425T001341
[2025-04-25T00:13:41.722+0000] {standard_task_runner.py:107} ERROR - Failed to execute job 10 for task extract_data (connection to server at "host.docker.internal" (192.168.65.254), port 5432 failed: fe_sendauth: no password supplied
; 183)
[2025-04-25T00:13:41.737+0000] {local_task_job_runner.py:234} INFO - Task exited with return code 1
[2025-04-25T00:13:41.820+0000] {taskinstance.py:3280} INFO - 0 downstream tasks scheduled from follow-on schedule check
